Workbook

Sheet OP
B2: Stock Performance | K2: Executive Summary | T2: Buy | Y2: Stock Price:
K4: Apple Inc. designs, manufactures, and markets smartphones, personal computers, tablets, wearables and accessories, and sells a variety of related accessories. The Company also offers payment, digital content, cloud and advertising services. Apple Inc.'s customers are primarily in consumer, small & mid-sized business, education, enterprise and government markets worldwide. | Y4: 45369 | Z4: 173.72
T5: BBG Ticker | U5: AAPL US EQUITY | Y5: 45370 | Z5: 176.08
T6: Price | U6: 252.65 | Y6: 45371 | Z6: 178.67
Y7: 45372 | Z7: 171.37
T8: Target Price | U8: ='DCF Model'!D83 | Y8: 45373 | Z8: 172.28
T9: Upside | U9: =IFERROR(U8/U6-1,"") | Y9: 45376 | Z9: 170.85
Y10: 45377 | Z10: 169.71
T11: Market Cap (Millions) | U11: 3718145.5 | Y11: 45378 | Z11: 173.31
Y12: 45379 | Z12: 171.48
Y13: 45383 | Z13: 170.03
Y14: 45384 | Z14: 168.84
Y15: 45385 | Z15: 169.65
B16: SWOT | T16: Statistics | Y16: 45386 | Z16: 168.82
B17: Strenghs | K17: Weaknesses | T17: Beta | U17: 1.0984648 | Y17: 45387 | Z17: 169.58
T18: % Float | U18: 0.9831211 | Y18: 45390 | Z18: 168.45
T19: % Held by Insiders | U19: 0.00065384194 | Y19: 45391 | Z19: 169.67
T20: % Held by Institutions | U20: 0.68672158 | Y20: 45392 | Z20: 167.78
Y21: 45393 | Z21: 175.04
Y22: 45394 | Z22: 176.55
Y23: 45397 | Z23: 172.69
B24: Opportunities | K24: Threats | Y24: 45398 | Z24: 169.38
Y25: 45399 | Z25: 168
Y26: 45400 | Z26: 167.04
Y27: 45401 | Z27: 165
Y28: 45404 | Z28: 165.84
Y29: 45405 | Z29: 166.9
Y30: 45406 | Z30: 169.02
Y31: 45407 | Z31: 169.89
Y32: 45408 | Z32: 169.3
Y33: 45411 | Z33: 173.5
Y34: 45412 | Z34: 170.33
Y35: 45413 | Z35: 169.3
Y36: 45414 | Z36: 173.03
... Y503: 46097 | Z503: 252.82

Sheet ESG
B3: Environmental | C3: Overview | D3: Targets | E3: Improvements | F3: Comments
B4: GHG Scope 1 Emissions
B6: Water Consumption
B8: Energy Consumption
B10: Waste Management
B12: Other
B15: Social | C15: Overview | D15: Targets | E15: Improvements | F15: Comments
B16: Employee Turnover %
B18: Salaries & Compensation
B20: Reputation
B22: Discrimination Events
B24: Work Safety
B26: Damage to consumer health
B28: Pension Plan
B30: Supply chain
B32: Community involvement
B34: Public Sector
B36: Litigation
B39: Governance | C39: Overview | D39: Targets | E39: Improvements | F39: Comments
B40: Diversity (Gender, Age, Industry, Region)
B42: % Independence
B44: Average time as independent directors
B46: Departures of C-level executives
B48: CEO/Chairman duality
B50: Transparency when reporting
B52: Time taken to report
B54: CEO or Chairman in other boards?
B56: Audit / Consulting
B58: ESG-compensation related
B60: Management compensation schemes

Sheet Peers
B2: Profitability Analysis | C2: Revenue Growth | D2: Gross Margin | E2: Operating Margin | F2: ROE | G2: ROA | H2: ROIC
A5: AAPL US Equity | B5: APPLE INC | C5: 0.064255118 | D5: 0.46905164 | E5: 0.319708 | F5: 1.5202132 | G5: 0.32562878 | H5: 0.8243537
A6: MU US Equity | B6: MICRON TECHNOLOGY INC | C6: 0.48851101 | D6: 0.39790786 | E6: 0.2613837 | F6: 0.22554283 | G6: 0.15129072 | H6: 0.20682606
A7: WDC US Equity | B7: WESTERN DIGITAL CORP | C7: 0.50704448 | D7: 0.38781513 | E7: 0.24516807 | F7: 0.38859887 | G7: 0.18632966 | H7: 0.1914533
A8: SNDK US Equity | B8: SANDISK CORP | C8: 0.10385712 | D8: 0.30074779 | E8: -0.18721958 | F8: -0.093724678 | G8: -0.076454172 | H8: -0.053604516
B11: Trading Multiples | C11: EV / SALES | D11: EV/ EBITDA | E11: EV/ EBIT | F11: Beta
B14: APPLE INC | C14: 7.7478963 | D14: 25.563399 | E14: 24.085684 | F14: 0.9497785
B15: MICRON TECHNOLOGY INC | C15: 5.416332 | D15: 7.6366209 | E15: 8.3373501 | F15: 2.4199562
B16: WESTERN DIGITAL CORP | C16: 7.1149121 | D16: 9.4455656 | E16: 18.822086 | F16: 2.3101215
B17: SANDISK CORP | C17: 4.5853746 | D17: 11.150597 | E17: 7.4444586 | F17: 3.3569829
A21: X | B21: Balance Sheet | C21: AAPL US Equity | D21: MU US Equity | E21: WDC US Equity | F21: SNDK US Equity | H21: Income Statement | I21: AAPL US Equity | J21: MU US Equity | K21: WDC US Equity | L21: SNDK US Equity
B24: Cash | C24: 35934 | D24: 1481 | E24: 2114 | F24: 1481 | H24: Revenue 2024 | I24: 391035 | J24: 25111 | K24: 6317 | L24: 6663
B25: Accounts receivable | C25: 39777 | D25: 1068 | E25: 1486 | F25: 1068 | H25: Revenue 2025 | I25: 416161 | J25: 37378 | K25: 9520 | L25: 7355
B26: Total Assets | C26: 359241 | D26: 12985 | E26: 14002 | F26: 12985 | H26: COGS | I26: 235478 | J26: 31765 | K26: 7747 | L26: 6283
B27: Current assets | C27: 147957 | D27: 5086 | E27: 5856 | F27: 5086 | H27: Gross Profit | I27: 180683 | J27: 5613 | K27: 1773 | L27: 1072
B28: Accounts payable | C28: 69860 | D28: 766 | E28: 1266 | F28: 766 | H28: EBITDA | I28: 136661 | J28: 9224 | K28: 206 | L28: #N/A N/A
B29: Current liabilities | C29: 165631 | D29: 1427 | E29: 5418 | F29: 1427 | H29: EBIT | I29: 123216 | J29: 1304 | K29: -403 | L29: -468
B30: Long-term debt | C30: 89931 | D30: 2022 | E30: 2595 | F30: 2022 | H30: Tax expense | I30: 29749 | J30: 451 | K30: 26 | L30: 169
B31: Total Liabilities | C31: 285508 | D31: 3769 | E31: 8462 | F31: 3769 | H31: Net income | I31: 93736 | J31: 778 | K31: -798 | L31: -672

Sheet Segments
B2: Segments | O2: Regions
D3: 2021 | E3: =D3+1 | F3: =E3+1 | G3: =F3+1 | H3: =G3+1 | I3: =H3+1 | J3: =I3+1 | K3: =J3+1 | L3: =K3+1 | M3: =L3+1 | Q3: 2021 | R3: =Q3+1 | S3: =R3+1 | T3: =S3+1 | U3: =T3+1
D4: FY | E4: FY | F4: FY | G4: FY | H4: FY | I4: FY | J4: FY | K4: FY | L4: FY | M4: FY | Q4: FY | R4: FY | S4: FY | T4: FY | U4: FY
B6: Segment 1 | I6: =H6*(1+I7) | J6: =I6*(1+J7) | K6: =J6*(1+K7) | L6: =K6*(1+L7) | M6: =L6*(1+M7) | O6: United States
B7: % Growth | E7: =E6/D6-1 | F7: =F6/E6-1 | G7: =G6/F6-1 | H7: =H6/G6-1 | O7: Taiwan
B8: % Total | D8: =D$6/D$18 | E8: =E$6/E$18 | F8: =F$6/F$18 | G8: =G$6/G$18 | H8: =H$6/H$18 | I8: =I$6/I$18 | J8: =J$6/J$18 | K8: =K$6/K$18 | ... M8: =M$6/M$18 | O8: Japan
B10: Segment 2 | I10: =H10*(1+I11) | J10: =I10*(1+J11) | K10: =J10*(1+K11) | L10: =K10*(1+L11) | M10: =L10*(1+M11) | O10: Other
B11: % Growth | E11: =E10/D10-1 | F11: =F10/E10-1 | G11: =G10/F10-1 | H11: =H10/G10-1 | O11: Other Asia Pacific
B12: % Total | D12: =D$10/D$18 | E12: =E$10/E$18 | F12: =F$10/F$18 | G12: =G$10/G$18 | H12: =H$10/H$18 | I12: =I$10/I$18 | J12: =J$10/J$18 | K12: =K$10/K$18 | ... M12: =M$10/M$18 | O12: Hong Kong
B14: Segment 3 | I14: =H14*(1+I15) | J14: =I14*(1+J15) | K14: =J14*(1+K15) | L14: =K14*(1+L15) | M14: =L14*(1+M15) | O14: Mainland China
B15: % Growth | E15: =E14/D14-1 | F15: =F14/E14-1 | G15: =G14/F14-1 | H15: =H14/G14-1 | O15: Europe
B16: % Total | D16: =D$14/D$18 | E16: =E$14/E$18 | F16: =F$14/F$18 | G16: =G$14/G$18 | H16: =H$14/H$18 | I16: =I$14/I$18 | J16: =J$14/J$18 | K16: =K$14/K$18 | ... M16: =M$14/M$18
B18: Total | D18: =D14+D10+D6 | E18: =E14+E10+E6 | F18: =F14+F10+F6 | G18: =G14+G10+G6 | H18: =H14+H10+H6 | I18: =I14+I10+I6 | J18: =J14+J10+J6 | K18: =K14+K10+K6 | ... M18: =M14+M10+M6 | O18: Total | Q18: =+SUM(Q6:Q15) | R18: =+SUM(R6:R15) | S18: =+SUM(S6:S15) | T18: =+SUM(T6:T15) | U18: =+SUM(U6:U15)
B20: Notes & Forecasts | O20: Notes & Forecasts

Sheet Industry
B2: Industry Growth Forecast
B4: in Billions of USD | D4: 2023 | E4: =+D4+1 | F4: =+E4+1 | G4: =+F4+1 | H4: =+G4+1 | I4: =+H4+1 | J4: =+I4+1 | K4: =+J4+1 | L4: ="CAGR "&$G$9&" - "&$K$9 | N4: vs Index
L7: =(K7/F7)^(1/5)-1
L8: =(K8/F8)^(1/5)-1
L9: =(K9/F9)^(1/5)-1
L10: =(K10/F10)^(1/5)-1
L11: =(K11/F11)^(1/5)-1
L12: =(K12/F12)^(1/5)-1
L13: =(I13/F13)^(1/3)-1
L14: =(I14/F14)^(1/3)-1
B18: Industry Driver | D18: Description | N18: Porter's Five Forces
N23: Rivalry Among Existing Competitors | R23: 5
N24: Threat of New Entrants | R24: 1
N25: Threat of Substitutes | R25: 2
N26: Bargaining Power of Customers | R26: 4
N27: Bargaining Power of Suppliers | R27: 3

Sheet WACC
B2: WACC | I2: Region | J2: Weight | K2: ERP
B6: Market Cap (in millions) | G6: =OP!U11 | I6: United States | K6: 0.0433 | L6: 0.0487
B7: % of Equity | G7: =IFERROR(G6/G20,"") | I7: Taiwan | K7: 0.0513 | L7: 0.0513
B8: Cost of Equity | G8: =IFERROR(G9+G11*G12,"") | I8: Japan | K8: 0.0527 | L8: 0.055
B9: Risk-Free Rate | G9: 0.0296 | I9: Other | K9: 0.06 | L9: 0.06
B10: Unlevered Beta | G10: 0.621 | I10: Other Asia Pacific | K10: =((6.46+4.33)/2)% | L10: 0.054
B11: Beta | G11: =OP!U17 | I11: Hong Kong | K11: 0.0513 | L11: 0.0525
B12: Equity Risk Premium | G12: 0.0539 | I12: Mainland China | K12: 0.0527 | L12: 0.0508
B13: Unlevered Cost of Equity | G13: =+G11*G12+G9 | I13: Europe | K13: 0.0513 | L13: 0.059
I14: Others | J14: =1-SUM(J6:J13) | K14: 0.0533 | L14: =+AVERAGE(L6:L13)
B15: Debt (in millions) | G15: 112377
B16: % of Debt | G16: =IFERROR(G15/G20,"")
B17: Cost of debt | G17: 0.043
B18: Tax Rate | G18: 0.21
B20: Total | G20: =+G6+G15
B22: WACC | G22: =IFERROR(G7*G8+G16*G17*(1-G18),"")

Sheet DCF Model
D3: 2021 | E3: 2022 | F3: 2023 | G3: 2024 | H3: 2025 | J3: 2026 | K3: 2027 | L3: 2028 | M3: 2029 | N3: 2030
D4: Historical | J4: Projected
B5: Income Statement | D5: 2021 | E5: 2022 | F5: 2023 | G5: 2024 | H5: 2025 | J5: 2026 | K5: 2027 | L5: 2028 | M5: 2029 | N5: 2030
B7: Revenue | D7: 365817 | E7: 394328 | F7: 383285 | G7: 391035 | H7: 416161 | J7: =+H7*(1+J8) | K7: =+J7*(1+K8) | L7: =+K7*(1+L8) | M7: =+L7*(1+M8) | N7: =+M7*(1+N8)
B8: Growth Rate | E8: 0.077937876 | F8: -0.028004605 | G8: 0.020219941 | H8: 0.064255118 | J8: =+AVERAGE(G8:H8) | K8: =+J8+0.5% | L8: =+K8+0.5% | M8: =+L8+0.5% | N8: =+M8+0.5%
B10: Gross Profit | D10: 152836 | E10: 170782 | F10: 169148 | G10: 180683 | H10: 195201 | J10: =+J7*J11 | K10: =+K7*K11 | L10: =+L7*L11 | M10: =+M7*M11 | N10: =+N7*N11
B11: Gross Margin | D11: 0.4177936 | E11: 0.43309631 | F11: 0.4413113 | G11: 0.4620635 | H11: 0.46905164 | J11: 0.47 | K11: 0.47 | L11: 0.47 | M11: 0.47 | N11: 0.47
B13: Research & Development | D13: 21914 | E13: 26251 | F13: 29915 | G13: 31370 | H13: 34550 | J13: =+J14*J7 | K13: =+K14*K7 | L13: =+L14*L7 | M13: =+M14*M7 | N13: =+N14*N7
B14: % of Revenue | D14: 0.059904269 | E14: 0.066571484 | F14: 0.078048971 | G14: 0.080222998 | H14: 0.083020754 | J14: 0.073553695 | K14: 0.073553695 | L14: 0.073553695 | M14: 0.073553695 | N14: 0.073553695
B16: SG&A & Other Operating Expenses | D16: 21973 | E16: 25094 | F16: 24932 | G16: 26097 | H16: 27601 | J16: =+J17*J7 | K16: =+K17*K7 | L16: =+L17*L7 | M16: =+M17*M7 | N16: =+N17*N7
B17: % of Revenue | D17: 0.060065552 | E17: 0.063637378 | F17: 0.065048202 | G17: 0.066738272 | H17: 0.066322889 | J17: 0.064362459 | K17: 0.064362459 | L17: 0.064362459 | M17: 0.064362459 | N17: 0.064362459
B19: Operating Income (EBIT) | D19: 108949 | E19: 119437 | F19: 114301 | G19: 123216 | H19: 133050 | J19: =J10-J13-J16 | K19: =K10-K13-K16 | L19: =L10-L13-L16 | M19: =M10-M13-M16 | N19: =N10-N13-N16
B20: Operating Margin | D20: 0.29782378 | E20: 0.30288744 | F20: 0.29821412 | G20: 0.31510223 | H20: 0.319708 | J20: =IFERROR(J19/J7,"") | K20: =IFERROR(K19/K7,"") | L20: =IFERROR(L19/L7,"") | M20: =IFERROR(M19/M7,"") | N20: =IFERROR(N19/N7,"")
B22: Cash Flow Items
B24: Depreciation & Amortization | D24: 11284 | E24: 11104 | F24: 11519 | G24: 11445 | H24: 11698 | J24: =+J25*$J$7 | K24: =+K25*K7 | L24: =+L25*L7 | M24: =+M25*M7 | N24: =+N25*N7
B25: % of Revenue | D25: 0.030846024 | E25: 0.028159299 | F25: 0.030053355 | G25: 0.02926848 | H25: 0.028109313 | J25: 0.028 | K25: 0.028 | L25: 0.028 | M25: 0.028 | N25: 0.028
B27: Stock-Based Compensation | D27: 7906 | E27: 9038 | F27: 10833 | G27: 11688 | H27: 12863 | J27: =+J28*J$7 | K27: =+K28*K$7 | L27: =+L28*L$7 | M27: =+M28*M$7 | N27: =+N28*N$7
B28: % of Revenue | D28: 0.021611899 | E28: 0.022920006 | F28: 0.028263564 | G28: 0.029889908 | H28: 0.030908711 | J28: 0.03 | K28: 0.03 | L28: 0.03 | M28: 0.03 | N28: 0.03
B30: Capital Expenditures | D30: -11085 | E30: -10708 | F30: -10959 | G30: -9447 | H30: -12715 | J30: =-J31*J$7 | K30: =-K31*K$7 | L30: =-L31*L$7 | M30: =-M31*M$7 | N30: =-N31*N$7
B31: % of Revenue | D31: 0.030302036 | E31: 0.027155059 | F31: 0.028592301 | G31: 0.024158963 | H31: 0.030553079 | J31: 0.03 | K31: 0.03 | L31: 0.03 | M31: 0.03 | N31: 0.03
B33: Change in Net Working Capital | D33: 210 | E33: -9080 | F33: 4213 | G33: -1492 | H33: 3899 | J33: =+J34*(J7-H7) | K33: =+K34*(K7-J7) | L33: =+L34*(L7-K7) | M33: =+M34*(M7-L7) | N33: =+N34*(N7-M7)
B34: % of Δ Revenue | E34: -0.31847357 | F34: -0.38150865 | G34: -0.19251613 | H34: 0.1551779 | J34: 0.1 | K34: 0.1 | L34: 0.1 | M34: 0.1 | N34: 0.1
B36: Unlevered Free Cash Flow
B38: EBIT | D38: 108949 | E38: 119437 | F38: 114301 | G38: 123216 | H38: 133050 | J38: =+J19 | K38: =+K19 | L38: =+L19 | M38: =+M19 | N38: =+N19
B39: Operating Margin | J39: =+J38/J7 | K39: =+K38/K7 | L39: =+L38/L7 | M39: =+M38/M7 | N39: =+N38/N7
B41: (-) Taxes on EBIT | D41: 14527 | E41: 19300 | F41: 16741 | G41: 29749 | H41: 20719 | J41: =+J38*J42 | K41: =+K38*K42 | L41: =+L38*L42 | M41: =+M38*M42 | N41: =+N38*N42
B42: Effective Tax Rate | D42: 0.13333762 | E42: 0.16159147 | F42: 0.14646416 | G42: 0.2414378 | H42: 0.15572341 | J42: 0.16 | K42: 0.16 | L42: 0.16 | M42: 0.16 | N42: 0.16
B44: EBIAT (NOPAT) | D44: 94422 | E44: 100137 | F44: 97560 | G44: 93467 | H44: 112331 | J44: =+J38-J41 | K44: =+K38-K41 | L44: =+L38-L41 | M44: =+M38-M41 | N44: =+N38-N41
B46: (+) D&A | D46: 11284 | E46: 11104 | F46: 11519 | G46: 11445 | H46: 11698 | J46: =+J24 | K46: =+K24 | L46: =+L24 | M46: =+M24 | N46: =+N24
B47: (-) Capital Expenditures | D47: -11085 | E47: -10708 | F47: -10959 | G47: -9447 | H47: -12715 | J47: =+J30 | K47: =+K30 | L47: =+L30 | M47: =+M30 | N47: =+N30
B48: (-) Change in NWC | D48: 210 | E48: -9080 | F48: 4213 | G48: -1492 | H48: 3899 | J48: =+J33 | K48: =+K33 | L48: =+L33 | M48: =+M33 | N48: =+N33
B50: Unlevered Free Cash Flow | D50: 94411 | E50: 109613 | F50: 93907 | G50: 96957 | H50: 107415 | J50: =J44+J46+J47-J48 | K50: =K44+K46+K47-K48 | L50: =L44+L46+L47-L48 | M50: =M44+M46+M47-M48 | N50: =N44+N46+N47-N48
B52: Discount Period (Mid-Year) | J52: 0.5 | K52: 1.5 | L52: 2.5 | M52: 3.5 | N52: 4.5
B53: Present Value of FCFF | D53: =IFERROR(D50/(1+WACC!$G$22)^D52,"") | E53: =IFERROR(E50/(1+WACC!$G$22)^E52,"") | F53: =IFERROR(F50/(1+WACC!$G$22)^F52,"") | G53: =IFERROR(G50/(1+WACC!$G$22)^G52,"") | H53: =IFERROR(H50/(1+WACC!$G$22)^H52,"") | J53: =IFERROR(J50/(1+$D$57)^J52,"") | K53: =IFERROR(K50/(1+$D$57)^K52,"") | L53: =IFERROR(L50/(1+$D$57)^L52,"") | M53: =IFERROR(M50/(1+$D$57)^M52,"") | N53: =IFERROR(N50/(1+$D$57)^N52,"")
B55: Terminal Value
B57: WACC | D57: =+WACC!G22
B58: Terminal Growth Rate | D58: 0.025
B59: Exit EV/EBITDA Multiple | D59: 22
B61: Gordon Growth Terminal Value | D61: =IFERROR($N$50*(1+$D$58)/($D$57-$D$58),"")
B62: Exit Multiple Terminal Value | D62: =IFERROR(($N$19+$N$24)*$D$59,"")
...

Sheet MC Assumptions
A1: Driver | B1: Label | C1: Shock Kind | D1: Spread | E1: Low | F1: High | G1: Per Year? | H1: Description
A2: revenue | B2: Revenue | C2: relative | D2: 0.05 | E2: 0.25 | F2: 2.5 | G2: Y | H2: Relative shock applied to projected revenue by year.
A3: cogs_pct | B3: COGS % | C3: additive | D3: 0.02 | E3: 0.05 | F3: 0.95 | G3: Y | H3: Additive shock to COGS as a percent of revenue.
A4: rd_pct | B4: R&D % | C4: additive | D4: 0.01 | E4: 0 | F4: 0.25 | G4: Y | H4: Additive shock to R&D as a percent of revenue.
A5: sga_pct | B5: SG&A % | C5: additive | D5: 0.015 | E5: 0.01 | F5: 0.6 | G5: Y | H5: Additive shock to SG&A as a percent of revenue.
A6: da_pct | B6: D&A % | C6: additive | D6: 0.01 | E6: 0 | F6: 0.25 | G6: Y | H6: Additive shock to D&A as a percent of revenue.
A7: tax_rate | B7: Tax Rate | C7: additive | D7: 0.015 | E7: 0 | F7: 0.45 | G7: Y | H7: Additive shock to the effective tax rate.
A8: capex | B8: CapEx | C8: relative | D8: 0.08 | E8: 0 | F8: 3 | G8: Y | H8: Relative shock applied to capital expenditures.
A9: nwc | B9: Change in NWC | C9: relative | D9: 0.1 | E9: 0 | F9: 3 | G9: Y | H9: Relative shock applied to change in working capital.
A10: wacc | B10: WACC | C10: additive | D10: 0.015 | E10: 0.04 | F10: 0.2 | G10: N | H10: Scalar shock to the discount rate.
A11: exit_multiple | B11: Exit Multiple | C11: additive | D11: 3 | E11: 4 | F11: 25 | G11: N | H11: Scalar shock to the exit EV/EBITDA multiple.
A12: terminal_g | B12: Terminal Growth | C12: additive | D12: 0.01 | E12: 0.005 | F12: 0.05 | G12: N | H12: Scalar shock to the terminal growth rate.

Sheet Results
A1: Monte Carlo Valuation Dashboard
A2: Workbook: Stock Pitch - mine Excel Model-1.xlsx
A3: Updated: 2026-03-17 15:34:42
A5: Summary | D5: Sensitivity Ranking
A6: Metric | B6: Value | D6: Parameter | E6: S1 | F6: S1_conf | G6: ST | H6: ST_conf
A7: Current Price | B7: 252.65 | D7: exit_multiple | E7: 0.44186024 | F7: 0.016818602 | G7: 0.4490829 | H7: 0.013014071
A8: Base DCF Target | B8: 236.31574 | D8: wacc | E8: 0.14509193 | F8: 0.011416853 | G8: 0.14917683 | H8: 0.0045648941
A9: Target Upside / Downside | B9: -0.064651717 | D9: cogs_pct | E9: 0.13922316 | F9: 0.010704885 | G9: 0.14218915 | H9: 0.0046356405
A10: Monte Carlo Mean | B10: 235.00927 | D10: revenue | E10: 0.11345977 | F10: 0.0087473942 | G10: 0.11637872 | H10: 0.0038991298
A11: Monte Carlo Median | B11: 234.01833 | D11: sga_pct | E11: 0.078375084 | F11: 0.0081056307 | G11: 0.079972461 | H11: 0.0025010801
A12: Monte Carlo Mean Upside / Downside | B12: -0.069822782 | D12: da_pct | E12: 0.036873512 | F12: 0.0053384999 | G12: 0.037852942 | H12: 0.0013649928
A13: Std Dev | B13: 38.235124 | D13: rd_pct | E13: 0.034708179 | F13: 0.0046229741 | G13: 0.035545018 | H13: 0.0013750092
A14: Probability Price > Current | B14: 0.31961726 | D14: tax_rate | E14: 0.00034268241 | F14: 0.00055075192 | G14: 0.00035986819 | H14: 1.2449287e-05
A15: Current Price Percentile Rank | B15: 0.68038274 | D15: capex | E15: 8.1807609e-05 | F15: 0.00026837731 | G15: 8.2521465e-05 | H15: 2.5358593e-06
A16: Iterations | B16: 1000000 | D16: nwc | E16: 4.0848073e-06 | F16: 6.0011483e-05 | G16: 3.4876021e-06 | H16: 1.1155674e-07
A17: Valid Draws | B17: 999946 | D17: terminal_g | E17: 0 | F17: 0 | G17: 0 | H17: 0
A18: Sobol Samples | B18: 8192
A19: Runtime (s) | B19: 1.544
D20: Tornado Sensitivity ($/share)
A21: Distribution Percentiles | D21: Label | E21: Shock Used | F21: Bear Delta | G21: Bull Delta | H21: Bear Price | I21: Bull Price
A22: Metric | B22: Value | D22: COGS % | E22: +/-2.0 pts | F22: -13.274435 | G22: 13.274435 | H22: 223.04131 | I22: 249.59018
A23: 5th Percentile | B23: 173.85255 | D23: WACC | E23: +/-100 bps | F23: -8.8191323 | G23: 9.2673014 | H23: 227.49661 | I23: 245.58305
A24: 25th Percentile | B24: 208.09892 | D24: Exit Multiple | E24: +/-1.0x | F24: -9.0372308 | G24: 9.0372308 | H24: 227.27851 | I24: 245.35297
A25: 50th Percentile | B25: 234.01833 | D25: D&A % | E25: +/-1.0 pt | F25: -6.8497413 | G25: 6.8497413 | H25: 229.466 | I25: 243.16549
A26: 75th Percentile | B26: 260.84571 | D26: R&D % | E26: +/-1.0 pt | F26: -6.6372173 | G26: 6.6372173 | H26: 229.67853 | I26: 242.95296
A27: 95th Percentile | B27: 299.41082 | D27: SG&A % | E27: +/-1.0 pt | F27: -6.6372173 | G27: 6.6372173 | H27: 229.67853 | I27: 242.95296
D28: Revenue | E28: +/-2.0% | F28: -4.7918108 | G28: 4.7918108 | H28: 231.52393 | I28: 241.10755
D29: CapEx Intensity | E29: +/-1.0 pt | F29: -1.3282751 | G29: 1.3282751 | H29: 234.98747 | I29: 237.64402
D30: Tax Rate | E30: +/-1.0 pt | F30: -0.44109869 | G30: 0.44109869 | H30: 235.87465 | I30: 236.75684
D31: Change in NWC | E31: +/-10.0% | F31: -0.06551909 | G31: 0.06551909 | H31: 236.25022 | I31: 236.38126
D32: Terminal Growth | E32: +/-50 bps | F32: 0 | G32: 0 | H32: 236.31574 | I32: 236.31574
